<?xml version="1.0"?>
<robot name="SpidermanRFootSphere">

  <link name="base_link"/>
  <joint name="base_link_J" type="fixed">
      <parent link="base_link"/>
      <child link="Pelvis"/>
      <origin rpy="0 0 0" xyz="0 0 0"/>
   </joint>

   <link name="Pelvis"/>
   
   <joint name="pelvis_rfoot_rom_joint" type="fixed">
      <parent link="Pelvis"/>
      <child link="pelvis_rfoot_rom"/>
      <origin rpy="0 0 0" xyz="0 0 0"/>
   </joint>

  <link name="pelvis_rfoot_rom">
      <visual>
         <origin xyz="0 0 0" rpy="0 0 0"/>
         <geometry>
            <mesh filename="package://hpp-rbprm-corba/meshes/spiderman/rfoot_rom.stl"/>
         </geometry>
      </visual>
	  <collision>
         <origin xyz="0 0 0" rpy="0 0 0"/>
         <geometry>
            <mesh filename="package://hpp-rbprm-corba/meshes/spiderman/rfoot_rom.stl"/>
         </geometry>
      </collision>
   </link>
   
   <link name="Thorax_rx"/>
   <link name="Thorax_ry"/>
   <link name="Thorax"/>
   <link name="Skull_rx"/>
   <link name="Skull_ry"/>
   <link name="Skull"/>

  <joint name="A_Thorax_rx" type="revolute"> <!-- A_ added for order while parsing with ROS -->
      <parent link="Pelvis"/>
      <child link="Thorax_rx"/>
      <origin rpy="0 0 0" xyz="0.0373 0.0006 0.0788"/>
      <axis xyz="1 0 0"/>
      <limit effort="0" lower="-1" upper="1" velocity="1.0"/>
   </joint>
   <joint name="Thorax_ry" type="revolute">
      <parent link="Thorax_rx"/>
      <child link="Thorax_ry"/>
      <origin rpy="0 0 0" xyz="0 0 0"/>
      <axis xyz="0 1 0"/>
      <limit effort="0" lower="-0.8" upper="0.8" velocity="1.0"/>
   </joint>
   <joint name="Thorax_rz" type="revolute">
      <parent link="Thorax_ry"/>
      <child link="Thorax"/>
      <origin rpy="0 0 0" xyz="0 0 0"/>
      <axis xyz="0 0 1"/>
      <limit effort="0" lower="-1.5" upper="1.5" velocity="1.0"/>
   </joint>
   <joint name="A_Skull_rx" type="revolute"> <!-- A_ added for order while parsing with ROS -->
      <parent link="Thorax"/>
      <child link="Skull_rx"/>
      <origin rpy="0 0 0" xyz="0.0711 -0.0005 0.6039"/>
      <axis xyz="1 0 0"/>
      <limit effort="0" lower="-0.3" upper="0.3" velocity="1.0"/>
   </joint>
   <joint name="Skull_ry" type="revolute">
      <parent link="Skull_rx"/>
      <child link="Skull_ry"/>
      <origin rpy="0 0 0" xyz="0 0 0"/>
      <axis xyz="0 1 0"/>
      <limit effort="0" lower="-1.1" upper="0.6" velocity="1.0"/>
   </joint>
   <joint name="Skull_rz" type="revolute">
      <parent link="Skull_ry"/>
      <child link="Skull"/>
      <origin rpy="0 0 0" xyz="0 0 0"/>
      <axis xyz="0 0 1"/>
      <limit effort="0" lower="-1.4" upper="1." velocity="1.0"/>
   </joint>
</robot>
