<robot name="hrp2_rleg_rom">
  <link name="base_link"/>
  <joint name="WAIST" type="fixed">
    <parent link="base_link"/>
    <child link="BODY"/>
    <origin rpy="0 0 0" xyz="0 0 0"/>
  </joint>
  <link name="BODY">   
    <visual>
      <origin xyz="0 0 0" rpy="0 0 0.003" />
      <geometry>
        <mesh filename="package://hpp-rbprm-corba/meshes/hrp2_rleg_rom.stl"/>
      </geometry>
      <material name="white">
        <color rgba="1 1 1 1"/>
      </material>
    </visual>
    <collision>
      <origin xyz="0 0 0" rpy="0 0 0.003" />
      <geometry>
        <mesh filename="package://hpp-rbprm-corba/meshes/hrp2_rleg_rom.stl"/>
      </geometry>
    </collision>
  </link>
  <!-- Chest -->
  <joint name="CHEST_JOINT0" type="revolute">
    <parent link="BODY"/>
    <child link="CHEST_LINK0"/>
    <origin rpy="0 0 0" xyz="0.032 0 0.3507"/>
    <axis xyz="0 0 1"/>
    <limit effort="151.1" lower="-0.785398" upper="0.785398" velocity="4.40217"/>
  </joint>
  <link name="CHEST_LINK0">
  </link>
  <joint name="CHEST_JOINT1" type="revolute">
    <parent link="CHEST_LINK0"/>
    <child link="torso"/>
    <origin rpy="0 0 0" xyz="0 0 0"/>
    <axis xyz="0 1 0"/>
    <limit effort="278.9" lower="-0.0872665" upper="1.0472" velocity="2.3963"/>
  </joint>
  <link name="torso">
  </link>!-- Head -->
  <joint name="HEAD_JOINT0" type="revolute">
    <parent link="torso"/>
    <child link="HEAD_LINK0"/>
    <origin rpy="0 -0 0" xyz="-0.007 0 0.2973"/>
    <axis xyz="0 0 1"/>
    <limit effort="9.6" lower="-0.785398" upper="0.785398" velocity="6.87679"/>
  </joint>
  <link name="HEAD_LINK0">
    <inertial>
      <origin rpy="0 0 0" xyz="-0.00087533 0.00426199 -0.00802747"/>
      <mass value="0.374766"/>
      <inertia ixx="0.00039945" ixy="-0.00000099" ixz="0.00000226" iyy="0.00022558" iyz="-0.00001181" izz="0.00036246"/>
    </inertial>
  </link>
  <joint name="HEAD_JOINT1" type="revolute">
    <parent link="HEAD_LINK0"/>
    <child link="HEAD_LINK1"/>
    <origin rpy="0 0 0" xyz="0 0 0"/>
    <axis xyz="0 1 0"/>
    <limit effort="9.6" lower="-0.523599" upper="0.785398" velocity="6.87679"/>
  </joint>
  <!-- VRML link name="HEAD_LINK1" -->
  <link name="HEAD_LINK1">
    <inertial>
      <origin rpy="0 0 0" xyz="0.01298846 0.00008605 0.07876058"/>
      <mass value="0.993355"/>
      <inertia ixx="0.00539717" ixy="-0.00002165" ixz="0.00069330" iyy="0.00457493" iyz="-0.00006372" izz="0.00590682"/>
    </inertial>
  </link>
</robot>
